<?xml version="1.0" ?>
<robot name="mobile_fr3_duo_v0_2">
  <link name="base"/>
  <joint name="base_joint" type="fixed">
    <parent link="base"/>
    <child link="base_link"/>
    <origin rpy="0 0 0" xyz="0 0 0"/>
  </joint>

  <link name="base_link">

  </link>

  <link name="base_inertia">
    <inertial>
      <origin rpy="0 0 0" xyz="0.006619 -0.002210 0.184355"/>
      <mass value="88.954183"/>
      <inertia ixx="3.245524271774" ixy="0.007060314402" ixz="-0.134604220439" iyy="4.162370636125" iyz="-0.010770547630" izz="5.841473351812"/>
    </inertial>
  </link>
  <joint name="base_inertia_joint" type="fixed">
    <parent link="base_link"/>
    <child link="base_inertia"/>
  </joint>

  <link name="caster_front_left_fixed_link">

    <inertial>
      <origin rpy="0 0 0" xyz="-0.02365 0.00005 -0.03651"/>
      <mass value="0.7"/>
      <inertia ixx="0.00049538079" ixy="-0.00000042663" ixz="0.00020926011" iyy="0.00070424109" iyz="-0.00000050221" izz="0.00048449394"/>
    </inertial>
  </link>
  <joint name="caster_front_left_fixed_joint" type="fixed">
    <origin xyz="0.3 0.2 0.08"/>
    <parent link="base_link"/>
    <child link="caster_front_left_fixed_link"/>
  </joint>
  <link name="caster_front_left_steering_link">
    <inertial>
      <origin rpy="0 0 0" xyz="0 0 0"/>
      <mass value="0.01"/>
      <inertia ixx="0.0001" ixy="0.0" ixz="0.0" iyy="0.0001" iyz="0.0" izz="0.0001"/>
    </inertial>
  </link>
  <joint name="caster_front_left_steering_joint" type="continuous">
    <origin xyz="0 0 0"/>
    <parent link="caster_front_left_fixed_link"/>
    <child link="caster_front_left_steering_link"/>
    <axis xyz="0 0 1"/>
    <limit effort="500" velocity="20"/>
    <dynamics damping="0.003" friction="0.0"/>
  </joint>
  <link name="caster_front_left_link">

    <inertial>
      <origin rpy="0 0 0" xyz="0 0 0"/>
      <mass value="0.001"/>
      <inertia ixx="0.0001" ixy="0.0" ixz="0.0" iyy="0.0001" iyz="0.0" izz="0.0001"/>
    </inertial>
  </link>
  <joint name="caster_front_left_joint" type="continuous">
    <origin rpy="0 0 0" xyz="-0.035 0 -0.05"/>
    <parent link="caster_front_left_steering_link"/>
    <child link="caster_front_left_link"/>
    <axis xyz="0 1 0"/>
    <limit effort="500" velocity="20"/>
    <dynamics damping="0.003" friction="0.0"/>
  </joint>

  <link name="argo_drive_front_fixed_link">

    <inertial>
      <origin rpy="0 0 0" xyz="-0.00019 0.04522 0.02947"/>
      <mass value="11.5"/>
      <inertia ixx="0.07060497424" ixy="-0.00025482709" ixz="-6.283102e-05" iyy="0.03433835031" iyz="0.00249596715" izz="0.08926325955"/>
    </inertial>
  </link>
  <joint name="argo_drive_front_fixed_joint" type="fixed">
    <origin xyz="0.3 -0.2 0.05"/>
    <parent link="base_link"/>
    <child link="argo_drive_front_fixed_link"/>
  </joint>
  <link name="argo_drive_front_steering_link">
    <inertial>
      <origin rpy="0 0 0" xyz="0 0 0"/>
      <mass value="2.0"/>
      <inertia ixx="0.1" ixy="0.0" ixz="0.0" iyy="0.1" iyz="0.0" izz="0.1"/>
    </inertial>
  </link>
  <joint name="tmrv0_2_joint_0" type="continuous">
    <origin xyz="0 0 0"/>
    <parent link="argo_drive_front_fixed_link"/>
    <child link="argo_drive_front_steering_link"/>
    <axis xyz="0 0 1"/>
    <limit effort="500" velocity="20"/>
    <dynamics damping="20.0" friction="5.0"/>
  </joint>
  <link name="argo_drive_front_link">

    <inertial>
      <mass value="2.5"/>
      <inertia ixx="0.0018958333333333336" ixy="0" ixz="0" iyy="0.0018958333333333336" iyz="0" izz="0.0031250000000000006"/>
    </inertial>
  </link>
  <joint name="tmrv0_2_joint_1" type="continuous">
    <origin rpy="0 0 0" xyz="0 0 0"/>
    <parent link="argo_drive_front_steering_link"/>
    <child link="argo_drive_front_link"/>
    <axis xyz="0 1 0"/>
    <limit effort="500" velocity="20"/>
    <dynamics damping="5.0" friction="1.0"/>
  </joint>

  <link name="rocker_arm_link">

    <inertial>
      <origin rpy="0 0 0" xyz="-0.000344 -0.021232 0.038239"/>
      <mass value="5.183973"/>
      <inertia ixx="0.077004518565" ixy="-0.000040505686" ixz="-0.000026300402" iyy="0.030693821144" iyz="0.002939677599" izz="0.083485865094"/>
    </inertial>
  </link>
  <joint name="rocker_arm_joint" type="revolute">
    <origin xyz="-0.3 0.0 0.0845"/>
    <parent link="base_link"/>
    <child link="rocker_arm_link"/>
    <axis xyz="1 0 0"/>
    <limit effort="500" lower="-0.16" upper="0.18" velocity="20"/>
    <dynamics damping="0.003" friction="0.0"/>
  </joint>

  <link name="caster_rear_right_fixed_link">

    <inertial>
      <origin rpy="0 0 0" xyz="-0.02365 0.00005 -0.03651"/>
      <mass value="0.7"/>
      <inertia ixx="0.00049538079" ixy="-0.00000042663" ixz="0.00020926011" iyy="0.00070424109" iyz="-0.00000050221" izz="0.00048449394"/>
    </inertial>
  </link>
  <joint name="caster_rear_right_fixed_joint" type="fixed">
    <origin xyz="0.0 -0.2 -0.004500000000000004"/>
    <parent link="rocker_arm_link"/>
    <child link="caster_rear_right_fixed_link"/>
  </joint>
  <link name="caster_rear_right_steering_link">
    <inertial>
      <origin rpy="0 0 0" xyz="0 0 0"/>
      <mass value="0.01"/>
      <inertia ixx="0.0001" ixy="0.0" ixz="0.0" iyy="0.0001" iyz="0.0" izz="0.0001"/>
    </inertial>
  </link>
  <joint name="caster_rear_right_steering_joint" type="continuous">
    <origin xyz="0 0 0"/>
    <parent link="caster_rear_right_fixed_link"/>
    <child link="caster_rear_right_steering_link"/>
    <axis xyz="0 0 1"/>
    <limit effort="500" velocity="20"/>
    <dynamics damping="0.003" friction="0.0"/>
  </joint>
  <link name="caster_rear_right_link">

    <inertial>
      <origin rpy="0 0 0" xyz="0 0 0"/>
      <mass value="0.001"/>
      <inertia ixx="0.0001" ixy="0.0" ixz="0.0" iyy="0.0001" iyz="0.0" izz="0.0001"/>
    </inertial>
  </link>
  <joint name="caster_rear_right_joint" type="continuous">
    <origin rpy="0 0 0" xyz="-0.035 0 -0.05"/>
    <parent link="caster_rear_right_steering_link"/>
    <child link="caster_rear_right_link"/>
    <axis xyz="0 1 0"/>
    <limit effort="500" velocity="20"/>
    <dynamics damping="0.003" friction="0.0"/>
  </joint>

  <link name="argo_drive_rear_fixed_link">

    <inertial>
      <origin rpy="0 0 0" xyz="-0.00019 -0.04522 0.02947"/>
      <mass value="11.5"/>
      <inertia ixx="0.07060497424" ixy="-0.00025482709" ixz="6.283102e-05" iyy="0.03433835031" iyz="-0.00249596715" izz="0.08926325955"/>
    </inertial>
  </link>
  <joint name="argo_drive_rear_fixed_joint" type="fixed">
    <origin xyz="0.0 0.2 -0.0345"/>
    <parent link="rocker_arm_link"/>
    <child link="argo_drive_rear_fixed_link"/>
  </joint>
  <link name="argo_drive_rear_steering_link">
    <inertial>
      <origin rpy="0 0 0" xyz="0 0 0"/>
      <mass value="2.0"/>
      <inertia ixx="0.1" ixy="0.0" ixz="0.0" iyy="0.1" iyz="0.0" izz="0.1"/>
    </inertial>
  </link>
  <joint name="tmrv0_2_joint_2" type="continuous">
    <origin xyz="0 0 0"/>
    <parent link="argo_drive_rear_fixed_link"/>
    <child link="argo_drive_rear_steering_link"/>
    <axis xyz="0 0 1"/>
    <limit effort="500" velocity="20"/>
    <dynamics damping="20.0" friction="5.0"/>
  </joint>
  <link name="argo_drive_rear_link">

    <inertial>
      <mass value="2.5"/>
      <inertia ixx="0.0018958333333333336" ixy="0" ixz="0" iyy="0.0018958333333333336" iyz="0" izz="0.0031250000000000006"/>
    </inertial>
  </link>
  <joint name="tmrv0_2_joint_3" type="continuous">
    <origin rpy="0 0 0" xyz="0 0 0"/>
    <parent link="argo_drive_rear_steering_link"/>
    <child link="argo_drive_rear_link"/>
    <axis xyz="0 1 0"/>
    <limit effort="500" velocity="20"/>
    <dynamics damping="5.0" friction="1.0"/>
  </joint>

  <link name="imu_mounting_point"/>
  <joint name="imu_mounting_point_joint" type="fixed">
    <parent link="base_link"/>
    <child link="imu_mounting_point"/>
    <origin rpy="3.141592653589793 0 0" xyz="0.260 0.0 0.1478"/>
  </joint>
  <link name="front_mounting_point"/>
  <joint name="front_mounting_point_joint" type="fixed">
    <parent link="base_link"/>
    <child link="front_mounting_point"/>
    <origin rpy="3.141592653589793 0 0" xyz="0.380705 0.0 0.2345"/>
  </joint>
  <link name="rear_mounting_point"/>
  <joint name="rear_mounting_point_joint" type="fixed">
    <parent link="base_link"/>
    <child link="rear_mounting_point"/>
    <origin rpy="3.141592653589793 0 3.141592653589793" xyz="-0.380705 0.0 0.2345"/>
  </joint>
  <link name="right_mounting_point"/>
  <joint name="right_mounting_point_joint" type="fixed">
    <parent link="base_link"/>
    <child link="right_mounting_point"/>
    <origin rpy="3.141592653589793 0 -1.5707963267948966" xyz="0.0 -0.272712 0.1145"/>
  </joint>
  <link name="left_mounting_point"/>
  <joint name="left_mounting_point_joint" type="fixed">
    <parent link="base_link"/>
    <child link="left_mounting_point"/>
    <origin rpy="3.141592653589793 0 1.5707963267948966" xyz="0.0 0.272712 0.1145"/>
  </joint>
  <link name="lidar_front_mounting_point"/>
  <joint name="lidar_front_mounting_point_joint" type="fixed">
    <parent link="base_link"/>
    <child link="lidar_front_mounting_point"/>
    <origin rpy="0 3.141592653589793 2.356194490192345" xyz="0.3275 0.2175 0.19065"/>
  </joint>
  <link name="lidar_rear_mounting_point"/>
  <joint name="lidar_rear_mounting_point_joint" type="fixed">
    <parent link="base_link"/>
    <child link="lidar_rear_mounting_point"/>
    <origin rpy="0 3.141592653589793 5.497787143782138" xyz="-0.3275 -0.2175 0.19065"/>
  </joint>

  <link name="franka_spine">

    <inertial>
      <origin rpy="0 0 0" xyz="0.042358 0.000378 0.495198"/>
      <mass value="21.909124"/>
      <inertia ixx="3.338968145" ixy="-0.000642887" ixz="0.299962762" iyy="3.324560297" iyz="-0.004488422" izz="0.281489258"/>
    </inertial>
  </link>
  <joint name="franka_spine_fixed_joint" type="fixed">
    <parent link="base_link"/>
    <child link="franka_spine"/>
    <origin rpy="0 0 0" xyz="0.138289 0.0 0.350"/>
  </joint>
  <link name="franka_spine_support">
    <inertial>
      <origin rpy="0 0 0" xyz="0 0 0"/>
      <mass value="0.01"/>
      <inertia ixx="0.0001" ixy="0.0" ixz="0.0" iyy="0.0001" iyz="0.0" izz="0.0001"/>
    </inertial>
  </link>
  <joint name="franka_spine_vertical_joint" type="prismatic">
    <parent link="franka_spine"/>
    <child link="franka_spine_support"/>
    <origin rpy="0 0 0" xyz="0.266711 0.0 0.1"/>
    <axis xyz="0 0 1"/>
    <limit effort="100" lower="0.0" upper="0.85" velocity="0.1"/>
  </joint>

  <link name="mount_link">

    <inertial>
      <origin rpy="0 0 0" xyz="-0.011817 -0.00005 0.044431"/>
      <mass value="4.093846"/>
      <inertia ixx="0.0224318121" ixy="1.38076e-06" ixz="-0.0015719371" iyy="0.0164193182" iyz="-1.442621e-06" izz="0.0217407036"/>
    </inertial>
  </link>
  <joint name="mount_joint" type="fixed">
    <origin rpy="0 0 0" xyz="0 0 0"/>
    <parent link="franka_spine_support"/>
    <child link="mount_link"/>
  </joint>

  <link name="head_link">

    <inertial>
      <mass value="1.0"/>
      <origin rpy="0 0 0" xyz="0 0 0"/>
      <inertia ixx="0.01" ixy="0.0" ixz="0.0" iyy="0.01" iyz="0.0" izz="0.01"/>
    </inertial>
  </link>
  <joint name="head_joint" type="fixed">
    <origin rpy="0 0 0" xyz="0 0 0.167"/>
    <parent link="mount_link"/>
    <child link="head_link"/>
  </joint>
  <link name="head_camera_mounting_point">
    <inertial>
      <mass value="0.001"/>
      <origin rpy="0 0 0" xyz="0 0 0"/>
      <inertia ixx="0.001" ixy="0.0" ixz="0.0" iyy="0.001" iyz="0.0" izz="0.001"/>
    </inertial>
  </link>
  <joint name="head_camera_mounting_point_joint" type="fixed">
    <origin rpy="0 0.7156 0" xyz="0.0498 -0.02 0.2345"/>
    <parent link="head_link"/>
    <child link="head_camera_mounting_point"/>
  </joint>

  <joint name="left_base_joint" type="fixed">
    <parent link="mount_link"/>
    <child link="left_base"/>
    <origin rpy="-0.89334809 -0.17456074 -0.46334506" xyz="0.0369 0.05018 0.050885"/>
  </joint>
  <link name="left_base"/>
  <joint name="left_fr3v2_left_base_joint" type="fixed">
    <parent link="left_base"/>
    <child link="left_fr3v2_link0"/>
    <origin rpy="0 0 0" xyz="0 0 0"/>
  </joint>

  <link name="left_fr3v2_link0">

    <inertial><origin rpy="0 0 0" xyz="-0.017200 0.000400 0.074500"/><mass value="2.3966"/><inertia ixx="0.009" ixy="0.0" ixz="0.002" iyy="0.0115" iyz="0.0" izz="0.0085"/></inertial>
  </link>
  <link name="left_fr3v2_link0_accelerometer_top"/>
  <joint name="left_fr3v2_link0_accelerometer_top_joint" type="fixed"><origin rpy="3.1416 0.0 0.0" xyz="-0.017402 -0.007872 0.04715"/><parent link="left_fr3v2_link0"/><child link="left_fr3v2_link0_accelerometer_top"/></joint>
  <link name="left_fr3v2_link0_accelerometer_bottom"/>
  <joint name="left_fr3v2_link0_accelerometer_bottom_joint" type="fixed"><origin rpy="0.0 0.0 -1.5708" xyz="-0.019739 0.0015506 0.05075"/><parent link="left_fr3v2_link0"/><child link="left_fr3v2_link0_accelerometer_bottom"/></joint>

  <link name="left_fr3v2_link1">

    <inertial><origin rpy="0 0 0" xyz="-0.004580 0.027016 -0.061800"/><mass value="2.4377"/><inertia ixx="0.02324" ixy="0.000333" ixz="-0.000676" iyy="0.02146" iyz="0.003739" izz="0.0055"/></inertial>
  </link>
  <link name="left_fr3v2_link1_accelerometer_top"/>
  <joint name="left_fr3v2_link1_accelerometer_top_joint" type="fixed"><origin rpy="-1.5708 0.0 3.1416" xyz="0.017402 -0.093352 -0.00787"/><parent link="left_fr3v2_link1"/><child link="left_fr3v2_link1_accelerometer_top"/></joint>
  <link name="left_fr3v2_link1_accelerometer_bottom"/>
  <joint name="left_fr3v2_link1_accelerometer_bottom_joint" type="fixed"><origin rpy="-1.5708 1.5708 0.0" xyz="0.01974 -0.08975 0.00155"/><parent link="left_fr3v2_link1"/><child link="left_fr3v2_link1_accelerometer_bottom"/></joint>
  <joint name="left_fr3v2_joint1" type="revolute">
    <origin rpy="0 0 0" xyz="0 0 0.333"/><parent link="left_fr3v2_link0"/><child link="left_fr3v2_link1"/><axis xyz="0 0 1"/>
    <limit effort="87.0" lower="-2.9007400166666666" upper="2.9007400166666666" velocity="2.62"/>
    <dynamics damping="0.003" friction="0.2"/>
  </joint>

  <link name="left_fr3v2_link2">

    <inertial><origin rpy="0 0 0" xyz="0.004541 -0.180691 -0.010479"/><mass value="2.2375"/><inertia ixx="0.019026" ixy="0.001241" ixz="0.000499" iyy="0.00566" iyz="-0.001804" izz="0.017114"/></inertial>
  </link>
  <link name="left_fr3v2_link2_accelerometer_top"/>
  <joint name="left_fr3v2_link2_accelerometer_top_joint" type="fixed"><origin rpy="1.5708 0.0 3.1416" xyz="0.017403 -0.11515 0.00787"/><parent link="left_fr3v2_link2"/><child link="left_fr3v2_link2_accelerometer_top"/></joint>
  <link name="left_fr3v2_link2_accelerometer_bottom"/>
  <joint name="left_fr3v2_link2_accelerometer_bottom_joint" type="fixed"><origin rpy="1.5708 -1.5708 0.0" xyz="0.019737 -0.11875 -0.00155"/><parent link="left_fr3v2_link2"/><child link="left_fr3v2_link2_accelerometer_bottom"/></joint>
  <joint name="left_fr3v2_joint2" type="revolute">
    <origin rpy="-1.570796326794897 0 0" xyz="0 0 0"/><parent link="left_fr3v2_link1"/><child link="left_fr3v2_link2"/><axis xyz="0 0 1"/>
    <limit effort="87.0" lower="-1.8360900166666667" upper="1.8360900166666667" velocity="2.62"/>
    <dynamics damping="0.003" friction="0.2"/>
  </joint>

  <link name="left_fr3v2_link3">

    <inertial><origin rpy="0 0 0" xyz="0.082540 0.019082 0.042027"/><mass value="2.193082"/><inertia ixx="0.010225" ixy="0.001144" ixz="0.003497" iyy="0.012398" iyz="0.002156" izz="0.006877"/></inertial>
  </link>
  <link name="left_fr3v2_link3_accelerometer_top"/>
  <joint name="left_fr3v2_link3_accelerometer_top_joint" type="fixed"><origin rpy="-1.5708 0.0 0.0" xyz="0.065099 0.077352 -0.00787"/><parent link="left_fr3v2_link3"/><child link="left_fr3v2_link3_accelerometer_top"/></joint>
  <link name="left_fr3v2_link3_accelerometer_bottom"/>
  <joint name="left_fr3v2_link3_accelerometer_bottom_joint" type="fixed"><origin rpy="1.5708 1.5708 0.0" xyz="0.062769 0.073756 0.00155"/><parent link="left_fr3v2_link3"/><child link="left_fr3v2_link3_accelerometer_bottom"/></joint>
  <joint name="left_fr3v2_joint3" type="revolute">
    <origin rpy="1.570796326794897 0 0" xyz="0 -0.316 0"/><parent link="left_fr3v2_link2"/><child link="left_fr3v2_link3"/><axis xyz="0 0 1"/>
    <limit effort="87.0" lower="-2.9007400166666666" upper="2.9007400166666666" velocity="2.62"/>
    <dynamics damping="0.003" friction="0.2"/>
  </joint>

  <link name="left_fr3v2_link4">

    <inertial><origin rpy="0 0 0" xyz="-0.087533 0.096335 0.010120"/><mass value="2.181537"/><inertia ixx="0.008878" ixy="-0.003749" ixz="0.001139" iyy="0.007628" iyz="-0.00046" izz="0.010295"/></inertial>
  </link>
  <link name="left_fr3v2_link4_accelerometer_top"/>
  <joint name="left_fr3v2_link4_accelerometer_top_joint" type="fixed"><origin rpy="-1.5708 0.0 -3.1416" xyz="-0.0651 0.046152 -0.00787"/><parent link="left_fr3v2_link4"/><child link="left_fr3v2_link4_accelerometer_top"/></joint>
  <link name="left_fr3v2_link4_accelerometer_bottom"/>
  <joint name="left_fr3v2_link4_accelerometer_bottom_joint" type="fixed"><origin rpy="-1.5708 1.5708 0.0" xyz="-0.062775 0.049753 0.00155"/><parent link="left_fr3v2_link4"/><child link="left_fr3v2_link4_accelerometer_bottom"/></joint>
  <joint name="left_fr3v2_joint4" type="revolute">
    <origin rpy="1.570796326794897 0 0" xyz="0.0825 0 0"/><parent link="left_fr3v2_link3"/><child link="left_fr3v2_link4"/><axis xyz="0 0 1"/>
    <limit effort="87.0" lower="-3.077020016666667" upper="-0.11693708333333333" velocity="2.62"/>
    <dynamics damping="0.003" friction="0.2"/>
  </joint>

  <link name="left_fr3v2_link5">

    <inertial><origin rpy="0 0 0" xyz="0.008383 0.010180 -0.053265"/><mass value="2.186881"/><inertia ixx="0.031874" ixy="0.000134" ixz="-0.000265" iyy="0.029674" iyz="-0.004734" izz="0.004751"/></inertial>
  </link>
  <link name="left_fr3v2_link5_accelerometer_top"/>
  <joint name="left_fr3v2_link5_accelerometer_top_joint" type="fixed"><origin rpy="-1.5708 0.0 0.0" xyz="-0.017363 0.085872 -0.00795"/><parent link="left_fr3v2_link5"/><child link="left_fr3v2_link5_accelerometer_top"/></joint>
  <link name="left_fr3v2_link5_accelerometer_bottom"/>
  <joint name="left_fr3v2_link5_accelerometer_bottom_joint" type="fixed"><origin rpy="1.5708 1.5708 0.0" xyz="-0.019742 0.082275 0.00146"/><parent link="left_fr3v2_link5"/><child link="left_fr3v2_link5_accelerometer_bottom"/></joint>
  <joint name="left_fr3v2_joint5" type="revolute">
    <origin rpy="-1.570796326794897 0 0" xyz="-0.0825 0.384 0"/><parent link="left_fr3v2_link4"/><child link="left_fr3v2_link5"/><axis xyz="0 0 1"/>
    <limit effort="12.0" lower="-2.87630335" upper="2.87630335" velocity="5.26"/>
    <dynamics damping="0.003" friction="0.2"/>
  </joint>

  <link name="left_fr3v2_link6">

    <inertial><origin rpy="0 0 0" xyz="0.070391 -0.016074 -0.035025"/><mass value="1.579681"/><inertia ixx="0.00286" ixy="-0.000553" ixz="-0.000638" iyy="0.00391" iyz="-0.00024" izz="0.00453"/></inertial>
  </link>
  <joint name="left_fr3v2_joint6" type="revolute">
    <origin rpy="1.570796326794897 0 0" xyz="0 0 0"/><parent link="left_fr3v2_link5"/><child link="left_fr3v2_link6"/><axis xyz="0 0 1"/>
    <limit effort="12.0" lower="0.43982265" upper="4.62163335" velocity="4.18"/>
    <dynamics damping="0.003" friction="0.2"/>
  </joint>

  <link name="left_fr3v2_link7">

    <inertial><origin rpy="0 0 0" xyz="-0.009108 0.018151 0.064946"/><mass value="0.694841"/><inertia ixx="0.000899" ixy="0.0" ixz="-1.3e-05" iyy="0.001099" iyz="-2.2e-05" izz="0.000702"/></inertial>
  </link>
  <joint name="left_fr3v2_joint7" type="revolute">
    <origin rpy="1.570796326794897 0 0" xyz="0.088 0 0"/><parent link="left_fr3v2_link6"/><child link="left_fr3v2_link7"/><axis xyz="0 0 1"/>
    <limit effort="12.0" lower="-3.05083335" upper="3.05083335" velocity="5.26"/>
    <dynamics damping="0.003" friction="0.2"/>
  </joint>

  <link name="left_fr3v2_link8"/>
  <joint name="left_fr3v2_joint8" type="fixed">
    <origin rpy="0 0 0" xyz="0 0 0.107"/>
    <parent link="left_fr3v2_link7"/>
    <child link="left_fr3v2_link8"/>
  </joint>

  <joint name="left_fr3v2_hand_joint" type="fixed">
    <parent link="left_fr3v2_link8"/>
    <child link="left_ChangingTek_AG2F120S"/>
    <origin rpy="0 0 -0.7853981633974483" xyz="0 0 0"/>
  </joint>

  <link name="left_ChangingTek_AG2F120S"/>

  <joint name="left_root_joint" type="fixed">
    <origin xyz="0. 0. 0." rpy="0. 0. 0."/>
    <parent link="left_ChangingTek_AG2F120S"/>
    <child link="left_ChangingTek_AG2F120S_gripper_base"/>
  </joint>

  <link name="left_ChangingTek_AG2F120S_gripper_base">
    <inertial>
      <origin xyz="0.0000012 0.0000003 0.0536187" rpy="0. 0. 0."/>
      <mass value="0.4431058"/>
      <inertia ixx="0.000642" ixy="-0.0000002" ixz="0." iyy="0.00067" iyz="0." izz="0.0002789"/>
    </inertial>

  </link>

  <joint name="left_left_gripper_joint" type="revolute">
    <origin xyz="-0.032553 0. 0.10644 " rpy="1.5707927 0. 0.0000072"/>
    <parent link="left_ChangingTek_AG2F120S_gripper_base"/>
    <child link="left_left_1_link"/>
    <axis xyz="0. 0. 1."/>
    <limit lower="0." upper="0.9999999" effort="5." velocity="999.9999621"/>
  </joint>
  <link name="left_left_1_link">
    <inertial>
      <origin xyz="0.0065639 0.0248503 -0. " rpy="0. 0. 0."/>
      <mass value="0.0112899"/>
      <inertia ixx="0.000002" ixy="0.0000006" ixz="0." iyy="0.0000014" iyz="0." izz="0.0000025"/>
    </inertial>

  </link>

  <joint name="left_left_2_joint" type="revolute">
    <origin xyz="-0.017 0. 0.122" rpy="1.5707927 0. 0.0000072"/>
    <parent link="left_ChangingTek_AG2F120S_gripper_base"/>
    <child link="left_left_2_link"/>
    <axis xyz="0. 0. 1."/>
    <limit lower="-0.2" upper="1.1999999" effort="0." velocity="17453.2925199"/>
  </joint>
  <link name="left_left_2_link">
    <inertial>
      <origin xyz="-0.0043895 0.0248816 -0.0000255" rpy="0. 0. 0."/>
      <mass value="0.0080396"/>
      <inertia ixx="0.0000012" ixy="0.0000001" ixz="-0." iyy="0.0000005" iyz="-0." izz="0.0000008"/>
    </inertial>

  </link>

  <joint name="left_left_support_joint" type="revolute">
    <origin xyz="0.0093594 0.056229 -0. " rpy="3.1415927 0. 3.1415927"/>
    <parent link="left_left_1_link"/>
    <child link="left_left_support_link"/>
    <axis xyz="0. 0. 1."/>
    <limit lower="-0.2" upper="1.1999999" effort="0." velocity="17453.2925199"/>
  </joint>
  <link name="left_left_support_link">
    <inertial>
      <origin xyz="-0.0139043 0.0281607 -0.0000011" rpy="0. 0. 0."/>
      <mass value="0.0173333"/>
      <inertia ixx="0.0000061" ixy="0.0000016" ixz="0." iyy="0.0000016" iyz="-0." izz="0.0000062"/>
    </inertial>

  </link>

  <joint name="left_right_1_joint" type="revolute">
    <origin xyz="0.032553 0. 0.10644 " rpy="1.5708 0. 0. "/>
    <parent link="left_ChangingTek_AG2F120S_gripper_base"/>
    <child link="left_right_1_link"/>
    <axis xyz="0. 0. 1."/>
    <limit lower="-1.1999999" upper="0.2" effort="0." velocity="17453.2925199"/>
  </joint>
  <link name="left_right_1_link">
    <inertial>
      <origin xyz="0.0065639 0.0248503 -0. " rpy="0. 0. 0."/>
      <mass value="0.0112899"/>
      <inertia ixx="0.000002" ixy="0.0000006" ixz="0." iyy="0.0000014" iyz="0." izz="0.0000025"/>
    </inertial>

  </link>

  <joint name="left_right_2_joint" type="revolute">
    <origin xyz="0.017 0. 0.122" rpy="1.5708 0. 0. "/>
    <parent link="left_ChangingTek_AG2F120S_gripper_base"/>
    <child link="left_right_2_link"/>
    <axis xyz="0. 0. 1."/>
    <limit lower="-1.4799998" upper="0.48" effort="0." velocity="17453.2925199"/>
  </joint>
  <link name="left_right_2_link">
    <inertial>
      <origin xyz="-0.0043895 0.0248816 -0.0000255" rpy="0. 0. 0."/>
      <mass value="0.0080396"/>
      <inertia ixx="0.0000012" ixy="0.0000001" ixz="-0." iyy="0.0000005" iyz="-0." izz="0.0000008"/>
    </inertial>

  </link>

  <joint name="left_right_support_joint" type="revolute">
    <origin xyz="-0.0093594 0.056229 -0. " rpy="-0.0000001 0. 0. "/>
    <parent link="left_right_1_link"/>
    <child link="left_right_support_link"/>
    <axis xyz="0. 0. 1."/>
    <limit lower="-0.48" upper="1.4799998" effort="0." velocity="17453.2925199"/>
  </joint>
  <link name="left_right_support_link">
    <inertial>
      <origin xyz="-0.0139043 0.0281607 -0.0000011" rpy="0. 0. 0."/>
      <mass value="0.0173333"/>
      <inertia ixx="0.0000061" ixy="0.0000016" ixz="0." iyy="0.0000016" iyz="-0." izz="0.0000062"/>
    </inertial>

  </link>

  <joint name="right_base_joint" type="fixed">
    <parent link="mount_link"/>
    <child link="right_base"/>
    <origin rpy="0.89334809 -0.17456074 0.46334506" xyz="0.0369 -0.05018 0.050885"/>
  </joint>
  <link name="right_base"/>
  <joint name="right_fr3v2_right_base_joint" type="fixed">
    <parent link="right_base"/>
    <child link="right_fr3v2_link0"/>
    <origin rpy="0 0 0" xyz="0 0 0"/>
  </joint>

  <link name="right_fr3v2_link0">

    <inertial><origin rpy="0 0 0" xyz="-0.017200 0.000400 0.074500"/><mass value="2.3966"/><inertia ixx="0.009" ixy="0.0" ixz="0.002" iyy="0.0115" iyz="0.0" izz="0.0085"/></inertial>
  </link>
  <link name="right_fr3v2_link0_accelerometer_top"/>
  <joint name="right_fr3v2_link0_accelerometer_top_joint" type="fixed"><origin rpy="3.1416 0.0 0.0" xyz="-0.017402 -0.007872 0.04715"/><parent link="right_fr3v2_link0"/><child link="right_fr3v2_link0_accelerometer_top"/></joint>
  <link name="right_fr3v2_link0_accelerometer_bottom"/>
  <joint name="right_fr3v2_link0_accelerometer_bottom_joint" type="fixed"><origin rpy="0.0 0.0 -1.5708" xyz="-0.019739 0.0015506 0.05075"/><parent link="right_fr3v2_link0"/><child link="right_fr3v2_link0_accelerometer_bottom"/></joint>

  <link name="right_fr3v2_link1">

    <inertial><origin rpy="0 0 0" xyz="-0.004580 0.027016 -0.061800"/><mass value="2.4377"/><inertia ixx="0.02324" ixy="0.000333" ixz="-0.000676" iyy="0.02146" iyz="0.003739" izz="0.0055"/></inertial>
  </link>
  <link name="right_fr3v2_link1_accelerometer_top"/>
  <joint name="right_fr3v2_link1_accelerometer_top_joint" type="fixed"><origin rpy="-1.5708 0.0 3.1416" xyz="0.017402 -0.093352 -0.00787"/><parent link="right_fr3v2_link1"/><child link="right_fr3v2_link1_accelerometer_top"/></joint>
  <link name="right_fr3v2_link1_accelerometer_bottom"/>
  <joint name="right_fr3v2_link1_accelerometer_bottom_joint" type="fixed"><origin rpy="-1.5708 1.5708 0.0" xyz="0.01974 -0.08975 0.00155"/><parent link="right_fr3v2_link1"/><child link="right_fr3v2_link1_accelerometer_bottom"/></joint>
  <joint name="right_fr3v2_joint1" type="revolute">
    <origin rpy="0 0 0" xyz="0 0 0.333"/><parent link="right_fr3v2_link0"/><child link="right_fr3v2_link1"/><axis xyz="0 0 1"/>
    <limit effort="87.0" lower="-2.9007400166666666" upper="2.9007400166666666" velocity="2.62"/>
    <dynamics damping="0.003" friction="0.2"/>
  </joint>

  <link name="right_fr3v2_link2">

    <inertial><origin rpy="0 0 0" xyz="0.004541 -0.180691 -0.010479"/><mass value="2.2375"/><inertia ixx="0.019026" ixy="0.001241" ixz="0.000499" iyy="0.00566" iyz="-0.001804" izz="0.017114"/></inertial>
  </link>
  <link name="right_fr3v2_link2_accelerometer_top"/>
  <joint name="right_fr3v2_link2_accelerometer_top_joint" type="fixed"><origin rpy="1.5708 0.0 3.1416" xyz="0.017403 -0.11515 0.00787"/><parent link="right_fr3v2_link2"/><child link="right_fr3v2_link2_accelerometer_top"/></joint>
  <link name="right_fr3v2_link2_accelerometer_bottom"/>
  <joint name="right_fr3v2_link2_accelerometer_bottom_joint" type="fixed"><origin rpy="1.5708 -1.5708 0.0" xyz="0.019737 -0.11875 -0.00155"/><parent link="right_fr3v2_link2"/><child link="right_fr3v2_link2_accelerometer_bottom"/></joint>
  <joint name="right_fr3v2_joint2" type="revolute">
    <origin rpy="-1.570796326794897 0 0" xyz="0 0 0"/><parent link="right_fr3v2_link1"/><child link="right_fr3v2_link2"/><axis xyz="0 0 1"/>
    <limit effort="87.0" lower="-1.8360900166666667" upper="1.8360900166666667" velocity="2.62"/>
    <dynamics damping="0.003" friction="0.2"/>
  </joint>

  <link name="right_fr3v2_link3">

    <inertial><origin rpy="0 0 0" xyz="0.082540 0.019082 0.042027"/><mass value="2.193082"/><inertia ixx="0.010225" ixy="0.001144" ixz="0.003497" iyy="0.012398" iyz="-0.002156" izz="0.006877"/></inertial>
  </link>
  <link name="right_fr3v2_link3_accelerometer_top"/>
  <joint name="right_fr3v2_link3_accelerometer_top_joint" type="fixed"><origin rpy="-1.5708 0.0 0.0" xyz="0.065099 0.077352 -0.00787"/><parent link="right_fr3v2_link3"/><child link="right_fr3v2_link3_accelerometer_top"/></joint>
  <link name="right_fr3v2_link3_accelerometer_bottom"/>
  <joint name="right_fr3v2_link3_accelerometer_bottom_joint" type="fixed"><origin rpy="1.5708 1.5708 0.0" xyz="0.062769 0.073756 0.00155"/><parent link="right_fr3v2_link3"/><child link="right_fr3v2_link3_accelerometer_bottom"/></joint>
  <joint name="right_fr3v2_joint3" type="revolute">
    <origin rpy="1.570796326794897 0 0" xyz="0 -0.316 0"/><parent link="right_fr3v2_link2"/><child link="right_fr3v2_link3"/><axis xyz="0 0 1"/>
    <limit effort="87.0" lower="-2.9007400166666666" upper="2.9007400166666666" velocity="2.62"/>
    <dynamics damping="0.003" friction="0.2"/>
  </joint>

  <link name="right_fr3v2_link4">

    <inertial><origin rpy="0 0 0" xyz="-0.087533 0.096335 0.010120"/><mass value="2.181537"/><inertia ixx="0.008878" ixy="-0.003749" ixz="0.001139" iyy="0.007628" iyz="-0.00046" izz="0.010295"/></inertial>
  </link>
  <link name="right_fr3v2_link4_accelerometer_top"/>
  <joint name="right_fr3v2_link4_accelerometer_top_joint" type="fixed"><origin rpy="-1.5708 0.0 -3.1416" xyz="-0.0651 0.046152 -0.00787"/><parent link="right_fr3v2_link4"/><child link="right_fr3v2_link4_accelerometer_top"/></joint>
  <link name="right_fr3v2_link4_accelerometer_bottom"/>
  <joint name="right_fr3v2_link4_accelerometer_bottom_joint" type="fixed"><origin rpy="-1.5708 1.5708 0.0" xyz="-0.062775 0.049753 0.00155"/><parent link="right_fr3v2_link4"/><child link="right_fr3v2_link4_accelerometer_bottom"/></joint>
  <joint name="right_fr3v2_joint4" type="revolute">
    <origin rpy="1.570796326794897 0 0" xyz="0.0825 0 0"/><parent link="right_fr3v2_link3"/><child link="right_fr3v2_link4"/><axis xyz="0 0 1"/>
    <limit effort="87.0" lower="-3.077020016666667" upper="-0.11693708333333333" velocity="2.62"/>
    <dynamics damping="0.003" friction="0.2"/>
  </joint>

  <link name="right_fr3v2_link5">

    <inertial><origin rpy="0 0 0" xyz="0.008383 0.010180 -0.053265"/><mass value="2.186881"/><inertia ixx="0.031874" ixy="0.000134" ixz="-0.000265" iyy="0.029674" iyz="-0.004734" izz="0.004751"/></inertial>
  </link>
  <link name="right_fr3v2_link5_accelerometer_top"/>
  <joint name="right_fr3v2_link5_accelerometer_top_joint" type="fixed"><origin rpy="-1.5708 0.0 0.0" xyz="-0.017363 0.085872 -0.00795"/><parent link="right_fr3v2_link5"/><child link="right_fr3v2_link5_accelerometer_top"/></joint>
  <link name="right_fr3v2_link5_accelerometer_bottom"/>
  <joint name="right_fr3v2_link5_accelerometer_bottom_joint" type="fixed"><origin rpy="1.5708 1.5708 0.0" xyz="-0.019742 0.082275 0.00146"/><parent link="right_fr3v2_link5"/><child link="right_fr3v2_link5_accelerometer_bottom"/></joint>
  <joint name="right_fr3v2_joint5" type="revolute">
    <origin rpy="-1.570796326794897 0 0" xyz="-0.0825 0.384 0"/><parent link="right_fr3v2_link4"/><child link="right_fr3v2_link5"/><axis xyz="0 0 1"/>
    <limit effort="12.0" lower="-2.87630335" upper="2.87630335" velocity="5.26"/>
    <dynamics damping="0.003" friction="0.2"/>
  </joint>

  <link name="right_fr3v2_link6">

    <inertial><origin rpy="0 0 0" xyz="0.070391 -0.016074 -0.035025"/><mass value="1.579681"/><inertia ixx="0.00286" ixy="-0.000553" ixz="-0.000638" iyy="0.00391" iyz="-0.00024" izz="0.00453"/></inertial>
  </link>
  <joint name="right_fr3v2_joint6" type="revolute">
    <origin rpy="1.570796326794897 0 0" xyz="0 0 0"/><parent link="right_fr3v2_link5"/><child link="right_fr3v2_link6"/><axis xyz="0 0 1"/>
    <limit effort="12.0" lower="0.43982265" upper="4.62163335" velocity="4.18"/>
    <dynamics damping="0.003" friction="0.2"/>
  </joint>

  <link name="right_fr3v2_link7">

    <inertial><origin rpy="0 0 0" xyz="-0.009108 0.018151 0.064946"/><mass value="0.694841"/><inertia ixx="0.000899" ixy="0.0" ixz="-1.3e-05" iyy="0.001099" iyz="-2.2e-05" izz="0.000702"/></inertial>
  </link>
  <joint name="right_fr3v2_joint7" type="revolute">
    <origin rpy="1.570796326794897 0 0" xyz="0.088 0 0"/><parent link="right_fr3v2_link6"/><child link="right_fr3v2_link7"/><axis xyz="0 0 1"/>
    <limit effort="12.0" lower="-3.05083335" upper="3.05083335" velocity="5.26"/>
    <dynamics damping="0.003" friction="0.2"/>
  </joint>

  <link name="right_fr3v2_link8"/>
  <joint name="right_fr3v2_joint8" type="fixed">
    <origin rpy="0 0 0" xyz="0 0 0.107"/>
    <parent link="right_fr3v2_link7"/>
    <child link="right_fr3v2_link8"/>
  </joint>

  <joint name="right_fr3v2_hand_joint" type="fixed">
    <parent link="right_fr3v2_link8"/>
    <child link="right_ChangingTek_AG2F120S"/>
    <origin rpy="0 0 -0.7853981633974483" xyz="0 0 0"/>
  </joint>

  <link name="right_ChangingTek_AG2F120S"/>

  <joint name="right_root_joint" type="fixed">
    <origin xyz="0. 0. 0." rpy="0. 0. 0."/>
    <parent link="right_ChangingTek_AG2F120S"/>
    <child link="right_ChangingTek_AG2F120S_gripper_base"/>
  </joint>

  <link name="right_ChangingTek_AG2F120S_gripper_base">
    <inertial>
      <origin xyz="0.0000012 0.0000003 0.0536187" rpy="0. 0. 0."/>
      <mass value="0.4431058"/>
      <inertia ixx="0.000642" ixy="-0.0000002" ixz="0." iyy="0.00067" iyz="0." izz="0.0002789"/>
    </inertial>

  </link>

  <joint name="right_left_gripper_joint" type="revolute">
    <origin xyz="-0.032553 0. 0.10644 " rpy="1.5707927 0. 0.0000072"/>
    <parent link="right_ChangingTek_AG2F120S_gripper_base"/>
    <child link="right_left_1_link"/>
    <axis xyz="0. 0. 1."/>
    <limit lower="0." upper="0.9999999" effort="5." velocity="999.9999621"/>
  </joint>
  <link name="right_left_1_link">
    <inertial>
      <origin xyz="0.0065639 0.0248503 -0. " rpy="0. 0. 0."/>
      <mass value="0.0112899"/>
      <inertia ixx="0.000002" ixy="0.0000006" ixz="0." iyy="0.0000014" iyz="0." izz="0.0000025"/>
    </inertial>

  </link>

  <joint name="right_left_2_joint" type="revolute">
    <origin xyz="-0.017 0. 0.122" rpy="1.5707927 0. 0.0000072"/>
    <parent link="right_ChangingTek_AG2F120S_gripper_base"/>
    <child link="right_left_2_link"/>
    <axis xyz="0. 0. 1."/>
    <limit lower="-0.2" upper="1.1999999" effort="0." velocity="17453.2925199"/>
  </joint>
  <link name="right_left_2_link">
    <inertial>
      <origin xyz="-0.0043895 0.0248816 -0.0000255" rpy="0. 0. 0."/>
      <mass value="0.0080396"/>
      <inertia ixx="0.0000012" ixy="0.0000001" ixz="-0." iyy="0.0000005" iyz="-0." izz="0.0000008"/>
    </inertial>

  </link>

  <joint name="right_left_support_joint" type="revolute">
    <origin xyz="0.0093594 0.056229 -0. " rpy="3.1415927 0. 3.1415927"/>
    <parent link="right_left_1_link"/>
    <child link="right_left_support_link"/>
    <axis xyz="0. 0. 1."/>
    <limit lower="-0.2" upper="1.1999999" effort="0." velocity="17453.2925199"/>
  </joint>
  <link name="right_left_support_link">
    <inertial>
      <origin xyz="-0.0139043 0.0281607 -0.0000011" rpy="0. 0. 0."/>
      <mass value="0.0173333"/>
      <inertia ixx="0.0000061" ixy="0.0000016" ixz="0." iyy="0.0000016" iyz="-0." izz="0.0000062"/>
    </inertial>

  </link>

  <joint name="right_right_1_joint" type="revolute">
    <origin xyz="0.032553 0. 0.10644 " rpy="1.5708 0. 0. "/>
    <parent link="right_ChangingTek_AG2F120S_gripper_base"/>
    <child link="right_right_1_link"/>
    <axis xyz="0. 0. 1."/>
    <limit lower="-1.1999999" upper="0.2" effort="0." velocity="17453.2925199"/>
  </joint>
  <link name="right_right_1_link">
    <inertial>
      <origin xyz="0.0065639 0.0248503 -0. " rpy="0. 0. 0."/>
      <mass value="0.0112899"/>
      <inertia ixx="0.000002" ixy="0.0000006" ixz="0." iyy="0.0000014" iyz="0." izz="0.0000025"/>
    </inertial>

  </link>

  <joint name="right_right_2_joint" type="revolute">
    <origin xyz="0.017 0. 0.122" rpy="1.5708 0. 0. "/>
    <parent link="right_ChangingTek_AG2F120S_gripper_base"/>
    <child link="right_right_2_link"/>
    <axis xyz="0. 0. 1."/>
    <limit lower="-1.4799998" upper="0.48" effort="0." velocity="17453.2925199"/>
  </joint>
  <link name="right_right_2_link">
    <inertial>
      <origin xyz="-0.0043895 0.0248816 -0.0000255" rpy="0. 0. 0."/>
      <mass value="0.0080396"/>
      <inertia ixx="0.0000012" ixy="0.0000001" ixz="-0." iyy="0.0000005" iyz="-0." izz="0.0000008"/>
    </inertial>

  </link>

  <joint name="right_right_support_joint" type="revolute">
    <origin xyz="-0.0093594 0.056229 -0. " rpy="-0.0000001 0. 0. "/>
    <parent link="right_right_1_link"/>
    <child link="right_right_support_link"/>
    <axis xyz="0. 0. 1."/>
    <limit lower="-0.48" upper="1.4799998" effort="0." velocity="17453.2925199"/>
  </joint>
  <link name="right_right_support_link">
    <inertial>
      <origin xyz="-0.0139043 0.0281607 -0.0000011" rpy="0. 0. 0."/>
      <mass value="0.0173333"/>
      <inertia ixx="0.0000061" ixy="0.0000016" ixz="0." iyy="0.0000016" iyz="-0." izz="0.0000062"/>
    </inertial>

  </link>

  <link name="left_tcp"/>
  <joint name="left_tcp_joint" type="fixed">
    <parent link="left_ChangingTek_AG2F120S_gripper_base"/>
    <child link="left_tcp"/>
    <origin rpy="0 0 0" xyz="0 0 0.22"/>
  </joint>

  <link name="right_tcp"/>
  <joint name="right_tcp_joint" type="fixed">
    <parent link="right_ChangingTek_AG2F120S_gripper_base"/>
    <child link="right_tcp"/>
    <origin rpy="0 0 0" xyz="0 0 0.22"/>
  </joint>

</robot>
